Workbook

Sheet 📊 Цены
A1: 📊 РЕАЛЬНЫЕ ЦЕНЫ ЗАКРЫТИЯ (126 торговых дней, Yahoo Finance)
A2: Период: 18.08.2025 — 17.02.2026. Цены в USD. S&P 500 — индекс рынка.
A3: Дата | B3: День | C3: PYPL (PayPal) | D3: MAR (Marriott International) | E3: MA (Mastercard ) | F3: GOOGL (Google) | G3: WMT (WalMart) | H3: BAIDF (Baidu) | I3: S&P 500
A4: 45887 | B4: 1 | C4: 69.37 | D4: 264.96 | E4: 582.49 | F4: 203.19 | G4: 100.5 | H4: 11.12 | I4: 6449.15
A5: 45888 | B5: 2 | C5: 68.89 | D5: 265.47 | E5: 583.86 | F5: 201.26 | G5: 101.08 | H5: 11.12 | I5: 6411.37
A6: 45889 | B6: 3 | C6: 67.92 | D6: 262.24 | E6: 591.01 | F6: 199.01 | G6: 102.36 | H6: 11.12 | I6: 6395.78
A7: 45890 | B7: 4 | C7: 67.39 | D7: 261.65 | E7: 590.25 | F7: 199.44 | G7: 97.76 | H7: 11.12 | I7: 6370.17
A8: 45891 | B8: 5 | C8: 69.74 | D8: 273.17 | E8: 597.27 | F8: 205.77 | G8: 96.63 | H8: 11.12 | I8: 6466.91
A9: 45894 | B9: 6 | C9: 69.32 | D9: 267.97 | E9: 591.54 | F9: 208.17 | G9: 95.87 | H9: 11.23 | I9: 6439.32
A10: 45895 | B10: 7 | C10: 70.02 | D10: 267.22 | E10: 589.94 | F10: 206.82 | G10: 95.85 | H10: 11.2 | I10: 6465.94
A11: 45896 | B11: 8 | C11: 69.49 | D11: 269.03 | E11: 589 | F11: 207.16 | G11: 95.88 | H11: 11.2 | I11: 6481.4
A12: 45897 | B12: 9 | C12: 69.9 | D12: 269.61 | E12: 588.82 | F12: 211.31 | G12: 95.91 | H12: 11.2 | I12: 6501.86
A13: 45898 | B13: 10 | C13: 70.03 | D13: 267.23 | E13: 593.61 | F13: 212.58 | G13: 96.78 | H13: 11.8 | I13: 6460.26
A14: 45902 | B14: 11 | C14: 69.09 | D14: 263.86 | E14: 590.2 | F14: 211.02 | G14: 97.65 | H14: 12.41 | I14: 6415.54
A15: 45903 | B15: 12 | C15: 69.48 | D15: 264.45 | E15: 591.61 | F15: 230.3 | G15: 99.24 | H15: 12.41 | I15: 6448.26
... A129: 46070 | B129: 126 | C129: 40.81 | D129: 359.94 | E129: 521.93 | F129: 302.02 | G129: 128.85 | H129: 17.94 | I129: 6843.22

Sheet 📈 Доходности
A1: 📈 ДОХОДНОСТИ И МЕТРИКИ — СЧИТАЕМ ИЗ РЕАЛЬНЫХ ЦЕН
A3: 📊 ШАГ 1: ДНЕВНЫЕ ДОХОДНОСТИ = (Цена_сегодня − Цена_вчера) / Цена_вчера
A5: Дата | B5: День | C5: PYPL (%) | D5: MAR (%) | E5: MA (%) | F5: GOOGL (%) | G5: WMT (%) | H5: BAIDF (%) | I5: S&P500 (%)
A6: ='📊 Цены'!A5 -> 45888 | B6: 2 | C6: =('📊 Цены'!C5-'📊 Цены'!C4)/'📊 Цены'!C4 -> -0.0069194176 | D6: =('📊 Цены'!D5-'📊 Цены'!D4)/'📊 Цены'!D4 -> 0.0019248188 | E6: =('📊 Цены'!E5-'📊 Цены'!E4)/'📊 Цены'!E4 -> 0.0023519717 | F6: =('📊 Цены'!F5-'📊 Цены'!F4)/'📊 Цены'!F4 -> -0.0094984989 | G6: =('📊 Цены'!G5-'📊 Цены'!G4)/'📊 Цены'!G4 -> 0.0057711443 | H6: =('📊 Цены'!H5-'📊 Цены'!H4)/'📊 Цены'!H4 -> 0 | I6: =('📊 Цены'!I5-'📊 Цены'!I4)/'📊 Цены'!I4 -> -0.0058581363 | K6: ← Из сырых цен!
A7: ='📊 Цены'!A6 -> 45889 | B7: 3 | C7: =('📊 Цены'!C6-'📊 Цены'!C5)/'📊 Цены'!C5 -> -0.014080418 | D7: =('📊 Цены'!D6-'📊 Цены'!D5)/'📊 Цены'!D5 -> -0.0121671 | E7: =('📊 Цены'!E6-'📊 Цены'!E5)/'📊 Цены'!E5 -> 0.012246086 | F7: =('📊 Цены'!F6-'📊 Цены'!F5)/'📊 Цены'!F5 -> -0.011179569 | G7: =('📊 Цены'!G6-'📊 Цены'!G5)/'📊 Цены'!G5 -> 0.012663237 | H7: =('📊 Цены'!H6-'📊 Цены'!H5)/'📊 Цены'!H5 -> 0 | I7: =('📊 Цены'!I6-'📊 Цены'!I5)/'📊 Цены'!I5 -> -0.0024316176
A8: ='📊 Цены'!A7 -> 45890 | B8: 4 | C8: =('📊 Цены'!C7-'📊 Цены'!C6)/'📊 Цены'!C6 -> -0.007803298 | D8: =('📊 Цены'!D7-'📊 Цены'!D6)/'📊 Цены'!D6 -> -0.0022498475 | E8: =('📊 Цены'!E7-'📊 Цены'!E6)/'📊 Цены'!E6 -> -0.0012859342 | F8: =('📊 Цены'!F7-'📊 Цены'!F6)/'📊 Цены'!F6 -> 0.0021606954 | G8: =('📊 Цены'!G7-'📊 Цены'!G6)/'📊 Цены'!G6 -> -0.044939429 | H8: =('📊 Цены'!H7-'📊 Цены'!H6)/'📊 Цены'!H6 -> 0 | I8: =('📊 Цены'!I7-'📊 Цены'!I6)/'📊 Цены'!I6 -> -0.0040042028
A9: ='📊 Цены'!A8 -> 45891 | B9: 5 | C9: =('📊 Цены'!C8-'📊 Цены'!C7)/'📊 Цены'!C7 -> 0.034871643 | D9: =('📊 Цены'!D8-'📊 Цены'!D7)/'📊 Цены'!D7 -> 0.044028282 | E9: =('📊 Цены'!E8-'📊 Цены'!E7)/'📊 Цены'!E7 -> 0.011893266 | F9: =('📊 Цены'!F8-'📊 Цены'!F7)/'📊 Цены'!F7 -> 0.031738869 | G9: =('📊 Цены'!G8-'📊 Цены'!G7)/'📊 Цены'!G7 -> -0.01155892 | H9: =('📊 Цены'!H8-'📊 Цены'!H7)/'📊 Цены'!H7 -> 0 | I9: =('📊 Цены'!I8-'📊 Цены'!I7)/'📊 Цены'!I7 -> 0.015186408
A10: ='📊 Цены'!A9 -> 45894 | B10: 6 | C10: =('📊 Цены'!C9-'📊 Цены'!C8)/'📊 Цены'!C8 -> -0.0060223688 | D10: =('📊 Цены'!D9-'📊 Цены'!D8)/'📊 Цены'!D8 -> -0.019035765 | E10: =('📊 Цены'!E9-'📊 Цены'!E8)/'📊 Цены'!E8 -> -0.0095936511 | F10: =('📊 Цены'!F9-'📊 Цены'!F8)/'📊 Цены'!F8 -> 0.011663508 | G10: =('📊 Цены'!G9-'📊 Цены'!G8)/'📊 Цены'!G8 -> -0.0078650523 | H10: =('📊 Цены'!H9-'📊 Цены'!H8)/'📊 Цены'!H8 -> 0.0098920863 | I10: =('📊 Цены'!I9-'📊 Цены'!I8)/'📊 Цены'!I8 -> -0.0042663343
A11: ='📊 Цены'!A10 -> 45895 | B11: 7 | C11: =('📊 Цены'!C10-'📊 Цены'!C9)/'📊 Цены'!C9 -> 0.010098096 | D11: =('📊 Цены'!D10-'📊 Цены'!D9)/'📊 Цены'!D9 -> -0.0027988208 | E11: =('📊 Цены'!E10-'📊 Цены'!E9)/'📊 Цены'!E9 -> -0.0027048044 | F11: =('📊 Цены'!F10-'📊 Цены'!F9)/'📊 Цены'!F9 -> -0.0064850843 | G11: =('📊 Цены'!G10-'📊 Цены'!G9)/'📊 Цены'!G9 -> -0.00020861583 | H11: =('📊 Цены'!H10-'📊 Цены'!H9)/'📊 Цены'!H9 -> -0.0026714159 | I11: =('📊 Цены'!I10-'📊 Цены'!I9)/'📊 Цены'!I9 -> 0.0041339769
A12: ='📊 Цены'!A11 -> 45896 | B12: 8 | C12: =('📊 Цены'!C11-'📊 Цены'!C10)/'📊 Цены'!C10 -> -0.0075692659 | D12: =('📊 Цены'!D11-'📊 Цены'!D10)/'📊 Цены'!D10 -> 0.0067734451 | E12: =('📊 Цены'!E11-'📊 Цены'!E10)/'📊 Цены'!E10 -> -0.0015933824 | F12: =('📊 Цены'!F11-'📊 Цены'!F10)/'📊 Цены'!F10 -> 0.0016439416 | G12: =('📊 Цены'!G11-'📊 Цены'!G10)/'📊 Цены'!G10 -> 0.00031298905 | H12: =('📊 Цены'!H11-'📊 Цены'!H10)/'📊 Цены'!H10 -> 0 | I12: =('📊 Цены'!I11-'📊 Цены'!I10)/'📊 Цены'!I10 -> 0.0023909903
A13: ='📊 Цены'!A12 -> 45897 | B13: 9 | C13: =('📊 Цены'!C12-'📊 Цены'!C11)/'📊 Цены'!C11 -> 0.0059001295 | D13: =('📊 Цены'!D12-'📊 Цены'!D11)/'📊 Цены'!D11 -> 0.0021558934 | E13: =('📊 Цены'!E12-'📊 Цены'!E11)/'📊 Цены'!E11 -> -0.00030560272 | F13: =('📊 Цены'!F12-'📊 Цены'!F11)/'📊 Цены'!F11 -> 0.020032825 | G13: =('📊 Цены'!G12-'📊 Цены'!G11)/'📊 Цены'!G11 -> 0.00031289111 | H13: =('📊 Цены'!H12-'📊 Цены'!H11)/'📊 Цены'!H11 -> 0 | I13: =('📊 Цены'!I12-'📊 Цены'!I11)/'📊 Цены'!I11 -> 0.0031567254
A14: ='📊 Цены'!A13 -> 45898 | B14: 10 | C14: =('📊 Цены'!C13-'📊 Цены'!C12)/'📊 Цены'!C12 -> 0.0018597997 | D14: =('📊 Цены'!D13-'📊 Цены'!D12)/'📊 Цены'!D12 -> -0.0088275657 | E14: =('📊 Цены'!E13-'📊 Цены'!E12)/'📊 Цены'!E12 -> 0.0081349139 | F14: =('📊 Цены'!F13-'📊 Цены'!F12)/'📊 Цены'!F12 -> 0.0060101273 | G14: =('📊 Цены'!G13-'📊 Цены'!G12)/'📊 Цены'!G12 -> 0.0090710041 | H14: =('📊 Цены'!H13-'📊 Цены'!H12)/'📊 Цены'!H12 -> 0.053571429 | I14: =('📊 Цены'!I13-'📊 Цены'!I12)/'📊 Цены'!I12 -> -0.0063981691
A15: ='📊 Цены'!A14 -> 45902 | B15: 11 | C15: =('📊 Цены'!C14-'📊 Цены'!C13)/'📊 Цены'!C13 -> -0.013422819 | D15: =('📊 Цены'!D14-'📊 Цены'!D13)/'📊 Цены'!D13 -> -0.01261086 | E15: =('📊 Цены'!E14-'📊 Цены'!E13)/'📊 Цены'!E13 -> -0.0057445124 | F15: =('📊 Цены'!F14-'📊 Цены'!F13)/'📊 Цены'!F13 -> -0.0073384138 | G15: =('📊 Цены'!G14-'📊 Цены'!G13)/'📊 Цены'!G13 -> 0.0089894606 | H15: =('📊 Цены'!H14-'📊 Цены'!H13)/'📊 Цены'!H13 -> 0.051694915 | I15: =('📊 Цены'!I14-'📊 Цены'!I13)/'📊 Цены'!I13 -> -0.006922322
A16: ='📊 Цены'!A15 -> 45903 | B16: 12 | C16: =('📊 Цены'!C15-'📊 Цены'!C14)/'📊 Цены'!C14 -> 0.0056448111 | D16: =('📊 Цены'!D15-'📊 Цены'!D14)/'📊 Цены'!D14 -> 0.0022360343 | E16: =('📊 Цены'!E15-'📊 Цены'!E14)/'📊 Цены'!E14 -> 0.0023890207 | F16: =('📊 Цены'!F15-'📊 Цены'!F14)/'📊 Цены'!F14 -> 0.091365747 | G16: =('📊 Цены'!G15-'📊 Цены'!G14)/'📊 Цены'!G14 -> 0.016282642 | H16: =('📊 Цены'!H15-'📊 Цены'!H14)/'📊 Цены'!H14 -> 0 | I16: =('📊 Цены'!I15-'📊 Цены'!I14)/'📊 Цены'!I14 -> 0.0051001163
A17: ='📊 Цены'!A16 -> 45904 | B17: 13 | C17: =('📊 Цены'!C16-'📊 Цены'!C15)/'📊 Цены'!C15 -> -0.016983305 | D17: =('📊 Цены'!D16-'📊 Цены'!D15)/'📊 Цены'!D15 -> 0.014256003 | E17: =('📊 Цены'!E16-'📊 Цены'!E15)/'📊 Цены'!E15 -> 0.0039722114 | F17: =('📊 Цены'!F16-'📊 Цены'!F15)/'📊 Цены'!F15 -> 0.0071211463 | G17: =('📊 Цены'!G16-'📊 Цены'!G15)/'📊 Цены'!G15 -> 0.014913341 | H17: =('📊 Цены'!H16-'📊 Цены'!H15)/'📊 Цены'!H15 -> -0.048348106 | I17: =('📊 Цены'!I16-'📊 Цены'!I15)/'📊 Цены'!I15 -> 0.0083464376
A18: ='📊 Цены'!A17 -> 45905 | B18: 14 | C18: =('📊 Цены'!C17-'📊 Цены'!C16)/'📊 Цены'!C16 -> -0.0029282577 | D18: =('📊 Цены'!D17-'📊 Цены'!D16)/'📊 Цены'!D16 -> -0.015435091 | E18: =('📊 Цены'!E17-'📊 Цены'!E16)/'📊 Цены'!E16 -> -0.019176376 | F18: =('📊 Цены'!F17-'📊 Цены'!F16)/'📊 Цены'!F16 -> 0.011640942 | G18: =('📊 Цены'!G17-'📊 Цены'!G16)/'📊 Цены'!G16 -> -0.004070691 | H18: =('📊 Цены'!H17-'📊 Цены'!H16)/'📊 Цены'!H16 -> 0.059271804 | I18: =('📊 Цены'!I17-'📊 Цены'!I16)/'📊 Цены'!I16 -> -0.003165141
... A130: ='📊 Цены'!A129 -> 46070 | B130: 126 | C130: =('📊 Цены'!C129-'📊 Цены'!C128)/'📊 Цены'!C128 -> 0.012906428 | D130: =('📊 Цены'!D129-'📊 Цены'!D128)/'📊 Цены'!D128 -> 0.017095708 | E130: =('📊 Цены'!E129-'📊 Цены'!E128)/'📊 Цены'!E128 -> 0.0068871055 | F130: =('📊 Цены'!F129-'📊 Цены'!F128)/'📊 Цены'!F128 -> -0.012102578 | G130: =('📊 Цены'!G129-'📊 Цены'!G128)/'📊 Цены'!G128 -> -0.037642841 | H130: =('📊 Цены'!H129-'📊 Цены'!H128)/'📊 Цены'!H128 -> 0 | I130: =('📊 Цены'!I129-'📊 Цены'!I128)/'📊 Цены'!I128 -> 0.0010312792
A132: 📊 ШАГ 2: СРЕДНЯЯ ДОХОДНОСТЬ И ВОЛАТИЛЬНОСТЬ
A134: Метрика | B134: PYPL | C134: MAR | D134: MA | E134: GOOGL | F134: WMT | G134: BAIDF | H134: S&P500
A135: Средняя дох-ть (дн.) | B135: =AVERAGE(C6:C130) -> -0.003855119 | C135: =AVERAGE(D6:D130) -> 0.002598202 | D135: =AVERAGE(E6:E130) -> -0.00079948555 | E135: =AVERAGE(F6:F130) -> 0.0033375605 | F135: =AVERAGE(G6:G130) -> 0.0021007138 | G135: =AVERAGE(H6:H130) -> 0.004769536 | H135: =AVERAGE(I6:I130) -> 0.00050095251
A136: Волатильность (дн.) | B136: =STDEV(C6:C130) -> 0.02670327 | C136: =STDEV(D6:D130) -> 0.017187071 | D136: =STDEV(E6:E130) -> 0.012589238 | E136: =STDEV(F6:F130) -> 0.018214638 | F136: =STDEV(G6:G130) -> 0.015015374 | G136: =STDEV(H6:H130) -> 0.043621019 | H136: =STDEV(I6:I130) -> 0.0072810621 | J136: ← STDEV = мера риска
A137: Годовая дох-ть | B137: =B135*252 -> -0.97148999 | C137: =C135*252 -> 0.65474691 | D137: =D135*252 -> -0.20147036 | E137: =E135*252 -> 0.84106524 | F137: =F135*252 -> 0.52937988 | G137: =G135*252 -> 1.2019231 | H137: =H135*252 -> 0.12624003 | J137: ← ×252 торговых дня
A138: Годовая волат-ть | B138: =B136*SQRT(252) -> 0.42390126 | C138: =C136*SQRT(252) -> 0.2728363 | D138: =D136*SQRT(252) -> 0.19984795 | E138: =E136*SQRT(252) -> 0.28914841 | F138: =F136*SQRT(252) -> 0.23836167 | G138: =G136*SQRT(252) -> 0.6924622 | H138: =H136*SQRT(252) -> 0.11558328
A140: 📊 ШАГ 3: БЕТА = COV(акция, S&P500) / VAR(S&P500)
A141: β>1 → рискованнее рынка. β<1 → спокойнее. β≈1 → как рынок.
A143: Метрика | B143: PYPL | C143: MAR | D143: MA | E143: GOOGL | F143: WMT | G143: BAIDF | H143: Пояснение
A144: Бета (β) | B144: =_xlfn.COVARIANCE.S(C6:C130,I6:I130)/_xlfn.VAR.S(I6:I130) -> 1.7264511 | C144: =_xlfn.COVARIANCE.S(D6:D130,I6:I130)/_xlfn.VAR.S(I6:I130) -> 0.74492777 | D144: =_xlfn.COVARIANCE.S(E6:E130,I6:I130)/_xlfn.VAR.S(I6:I130) -> 0.44310214 | E144: =_xlfn.COVARIANCE.S(F6:F130,I6:I130)/_xlfn.VAR.S(I6:I130) -> 1.2134568 | F144: =_xlfn.COVARIANCE.S(G6:G130,I6:I130)/_xlfn.VAR.S(I6:I130) -> -0.14409512 | G144: =_xlfn.COVARIANCE.S(H6:H130,I6:I130)/_xlfn.VAR.S(I6:I130) -> 0.45176473 | I144: ← COV/VAR из реальных данных!
A145: Тип: | B145: =IF(B144>1.2,"⚡ Агрессивная",IF(B144<0.8,"🛡️ Защитная","➡️ Нейтральная")) -> ⚡ Агрессивная | C145: =IF(C144>1.2,"⚡ Агрессивная",IF(C144<0.8,"🛡️ Защитная","➡️ Нейтральная")) -> 🛡️ Защитная | D145: =IF(D144>1.2,"⚡ Агрессивная",IF(D144<0.8,"🛡️ Защитная","➡️ Нейтральная")) -> 🛡️ Защитная | E145: =IF(E144>1.2,"⚡ Агрессивная",IF(E144<0.8,"🛡️ Защитная","➡️ Нейтральная")) -> ⚡ Агрессивная | F145: =IF(F144>1.2,"⚡ Агрессивная",IF(F144<0.8,"🛡️ Защитная","➡️ Нейтральная")) -> 🛡️ Защитная | G145: =IF(G144>1.2,"⚡ Агрессивная",IF(G144<0.8,"🛡️ Защитная","➡️ Нейтральная")) -> 🛡️ Защитная
A147: 📊 ШАГ 4: ШАРП = (Год.дох-ть − 5.25%) / Год.волат-ть
A148: Безрисковая ставка = 5.25% (Fed Funds Rate). Sharpe>1 = хорошо.
A150: Метрика | B150: PYPL | C150: MAR | D150: MA | E150: GOOGL | F150: WMT | G150: BAIDF | H150: Пояснение
A151: Безриск. ставка | B151: 0.0525 | C151: 0.0525 | D151: 0.0525 | E151: 0.0525 | F151: 0.0525 | G151: 0.0525
A152: Sharpe Ratio ✨ | B152: =(B137-B151)/B138 -> -2.4156333 | C152: =(C137-C151)/C138 -> 2.2073563 | D152: =(D137-D151)/D138 -> -1.2708179 | E152: =(E137-E151)/E138 -> 2.727199 | F152: =(F137-F151)/F138 -> 2.0006567 | G152: =(G137-G151)/G138 -> 1.6599073
A153: Оценка: | B153: =IF(B152>1,"⭐ Отличная",IF(B152>0,"👍 ОК","👎 Хуже депозита")) -> 👎 Хуже депозита | C153: =IF(C152>1,"⭐ Отличная",IF(C152>0,"👍 ОК","👎 Хуже депозита")) -> ⭐ Отличная | D153: =IF(D152>1,"⭐ Отличная",IF(D152>0,"👍 ОК","👎 Хуже депозита")) -> 👎 Хуже депозита | E153: =IF(E152>1,"⭐ Отличная",IF(E152>0,"👍 ОК","👎 Хуже депозита")) -> ⭐ Отличная | F153: =IF(F152>1,"⭐ Отличная",IF(F152>0,"👍 ОК","👎 Хуже депозита")) -> ⭐ Отличная | G153: =IF(G152>1,"⭐ Отличная",IF(G152>0,"👍 ОК","👎 Хуже депозита")) -> ⭐ Отличная
A155: 🏆 Всё посчитано из РЕАЛЬНЫХ цен Yahoo Finance! Бета и Шарп — настоящие значения.

Sheet 📊 Корреляция
A1: 📊 КОРРЕЛЯЦИЯ ДОХОДНОСТЕЙ (РЕАЛЬНЫЕ ДАННЫЕ)
A3: ❓ Какие акции ходят вместе? Для портфеля нужны НЕКОРРЕЛИРОВАННЫЕ!
B5: PYPL | C5: MAR | D5: MA | E5: GOOGL | F5: WMT | G5: BAIDF
A6: PYPL | B6: 1 | C6: =CORREL('📈 Доходности'!C6:C130,'📈 Доходности'!D6:D130) -> 0.2293933 | D6: =CORREL('📈 Доходности'!C6:C130,'📈 Доходности'!E6:E130) -> 0.2652691 | E6: =CORREL('📈 Доходности'!C6:C130,'📈 Доходности'!F6:F130) -> 0.14814331 | F6: =CORREL('📈 Доходности'!C6:C130,'📈 Доходности'!G6:G130) -> -0.1695941 | G6: =CORREL('📈 Доходности'!C6:C130,'📈 Доходности'!H6:H130) -> 0.20500636
A7: MAR | B7: =CORREL('📈 Доходности'!D6:D130,'📈 Доходности'!C6:C130) -> 0.2293933 | C7: 1 | D7: =CORREL('📈 Доходности'!D6:D130,'📈 Доходности'!E6:E130) -> 0.4789858 | E7: =CORREL('📈 Доходности'!D6:D130,'📈 Доходности'!F6:F130) -> 0.03293207 | F7: =CORREL('📈 Доходности'!D6:D130,'📈 Доходности'!G6:G130) -> 0.037272355 | G7: =CORREL('📈 Доходности'!D6:D130,'📈 Доходности'!H6:H130) -> -0.038155181
A8: MA | B8: =CORREL('📈 Доходности'!E6:E130,'📈 Доходности'!C6:C130) -> 0.2652691 | C8: =CORREL('📈 Доходности'!E6:E130,'📈 Доходности'!D6:D130) -> 0.4789858 | D8: 1 | E8: =CORREL('📈 Доходности'!E6:E130,'📈 Доходности'!F6:F130) -> 0.051352586 | F8: =CORREL('📈 Доходности'!E6:E130,'📈 Доходности'!G6:G130) -> 0.15684775 | G8: =CORREL('📈 Доходности'!E6:E130,'📈 Доходности'!H6:H130) -> 0.23332698
A9: GOOGL | B9: =CORREL('📈 Доходности'!F6:F130,'📈 Доходности'!C6:C130) -> 0.14814331 | C9: =CORREL('📈 Доходности'!F6:F130,'📈 Доходности'!D6:D130) -> 0.03293207 | D9: =CORREL('📈 Доходности'!F6:F130,'📈 Доходности'!E6:E130) -> 0.051352586 | E9: 1 | F9: =CORREL('📈 Доходности'!F6:F130,'📈 Доходности'!G6:G130) -> -0.086149724 | G9: =CORREL('📈 Доходности'!F6:F130,'📈 Доходности'!H6:H130) -> 0.061550492
A10: WMT | B10: =CORREL('📈 Доходности'!G6:G130,'📈 Доходности'!C6:C130) -> -0.1695941 | C10: =CORREL('📈 Доходности'!G6:G130,'📈 Доходности'!D6:D130) -> 0.037272355 | D10: =CORREL('📈 Доходности'!G6:G130,'📈 Доходности'!E6:E130) -> 0.15684775 | E10: =CORREL('📈 Доходности'!G6:G130,'📈 Доходности'!F6:F130) -> -0.086149724 | F10: 1 | G10: =CORREL('📈 Доходности'!G6:G130,'📈 Доходности'!H6:H130) -> -0.0023354868
A11: BAIDF | B11: =CORREL('📈 Доходности'!H6:H130,'📈 Доходности'!C6:C130) -> 0.20500636 | C11: =CORREL('📈 Доходности'!H6:H130,'📈 Доходности'!D6:D130) -> -0.038155181 | D11: =CORREL('📈 Доходности'!H6:H130,'📈 Доходности'!E6:E130) -> 0.23332698 | E11: =CORREL('📈 Доходности'!H6:H130,'📈 Доходности'!F6:F130) -> 0.061550492 | F11: =CORREL('📈 Доходности'!H6:H130,'📈 Доходности'!G6:G130) -> -0.0023354868 | G11: 1
A13: 📋 КЛЮЧЕВЫЕ ПАРЫ:
A14: Пара | C14: r | D14: Сила | F14: Для портфеля
A15: PYPL↔MA | C15: =D6 -> 0.2652691 | D15: =IF(ABS(C6)>=0.7,"🟢 Сильная",IF(ABS(C6)>=0.3,"🟡 Средняя","🔴 Слабая")) -> 🔴 Слабая | F15: Два гиганта в сфере цифровых платежей — диверсификация?
A16: PYPL↔GOOGL | C16: =E6 -> 0.14814331 | D16: =IF(ABS(F6)>=0.7,"🟢 Сильная",IF(ABS(F6)>=0.3,"🟡 Средняя","🔴 Слабая")) -> 🔴 Слабая | F16: Если связь технологичности цифровых платежей и сектора технологии
A17: GOOGL↔BAIDF | C17: =G9 -> 0.061550492 | D17: =IF(ABS(E8)>=0.7,"🟢 Сильная",IF(ABS(E8)>=0.3,"🟡 Средняя","🔴 Слабая")) -> 🔴 Слабая | F17: Два тех-гиганта — география
A18: MAR↔WMT | C18: =F7 -> 0.037272355 | D18: =IF(ABS(G10)>=0.7,"🟢 Сильная",IF(ABS(G10)>=0.3,"🟡 Средняя","🔴 Слабая")) -> 🔴 Слабая | F18: отдух/досуг и потребительские товары — для диверсификации
A19: PYPL↔BAIDF | C19: =G6 -> 0.20500636 | D19: =IF(ABS(G7)>=0.7,"🟢 Сильная",IF(ABS(G7)>=0.3,"🟡 Средняя","🔴 Слабая")) -> 🔴 Слабая | F19: Если связь технологичности цифровых платежей и сектора технологии (Китай)
A21: ✏️ ЗНАЧИМОСТЬ (t-тест)
A22: t = r×√(n-2)/√(1-r²). t_крит ≈ 2.05 при α=0.05, df=123.
A24: Пара | C24: r | D24: n | E24: t-стат | F24: t-крит | G24: Значима? | I24: Вывод
A25: PYPL↔MA | C25: =C15 -> 0.2652691 | D25: 125 | E25: =C25*SQRT(125-2)/SQRT(1-C25^2) -> 3.0512909 | F25: 2.05 | G25: =IF(ABS(E25)>2.05,"✅ Реальная","❌ Случайная") -> ✅ Реальная | I25: =IF(ABS(E25)>2.05,"Учитывать в портфеле","Игнорировать") -> Учитывать в портфеле
A26: PYPL↔GOOGL | C26: =C16 -> 0.14814331 | D26: 125 | E26: =C26*SQRT(125-2)/SQRT(1-C26^2) -> 1.66132 | F26: 2.05 | G26: =IF(ABS(E26)>2.05,"✅ Реальная","❌ Случайная") -> ❌ Случайная | I26: =IF(ABS(E26)>2.05,"Учитывать в портфеле","Игнорировать") -> Игнорировать
A27: GOOGL↔BAIDF | C27: =C17 -> 0.061550492 | D27: 125 | E27: =C27*SQRT(125-2)/SQRT(1-C27^2) -> 0.68392472 | F27: 2.05 | G27: =IF(ABS(E27)>2.05,"✅ Реальная","❌ Случайная") -> ❌ Случайная | I27: =IF(ABS(E27)>2.05,"Учитывать в портфеле","Игнорировать") -> Игнорировать
A28: MAR↔WMT | C28: =C18 -> 0.037272355 | D28: 125 | E28: =C28*SQRT(125-2)/SQRT(1-C28^2) -> 0.41365784 | F28: 2.05 | G28: =IF(ABS(E28)>2.05,"✅ Реальная","❌ Случайная") -> ❌ Случайная | I28: =IF(ABS(E28)>2.05,"Учитывать в портфеле","Игнорировать") -> Игнорировать
A29: PYPL↔BAIDF | C29: =C19 -> 0.20500636 | D29: 125 | E29: =C29*SQRT(125-2)/SQRT(1-C29^2) -> 2.3229689 | F29: 2.05 | G29: =IF(ABS(E29)>2.05,"✅ Реальная","❌ Случайная") -> ✅ Реальная | I29: =IF(ABS(E29)>2.05,"Учитывать в портфеле","Игнорировать") -> Учитывать в портфеле
A31: По итогам проведенного анализа, выбранные пары имеют слабую корреляционную связь. Максимальное значение r = 0,265. То есть выбранные акции достаточно независимы друг от друга. Но если рассматривать в рамках t-теста, то самые наиболее статистически значимые связи у пар: 1- PayPal и Mastercard, 2- PayPal и Baidu. Первая связь логична, это компании аналагичного бизнеса. Связь второй пары скорее носит случайный характер,нежели какую-то закономерность.

Sheet 📈 Регрессия
A1: 📈 РЕГРЕССИЯ: PYPL ~ S&P 500 (CAPM)
A3: ❓ CAPM: Доходность_PYPL = α + β × Доходность_SP500
A4: Paypal — самая волатильная из наших акций. Как она зависит от рынка?
A5: α > 0 → Paypal обыгрывает рынок! β > 1 → рискованнее рынка.
A7: 📊 МЕТРИКИ CAPM
A8: Параметр | B8: Значение | C8: Формула | E8: Что это значит
A9: α (альфа) | B9: =INTERCEPT('📈 Доходности'!C6:C130,'📈 Доходности'!I6:I130) -> -0.004719989 | C9: INTERCEPT(PYPL, SP500) | E9: ← α>0 → PYPL обыгрывает рынок!
A10: β (бета) | B10: =SLOPE('📈 Доходности'!C6:C130,'📈 Доходности'!I6:I130) -> 1.7264511 | C10: SLOPE(PYPL, SP500) | E10: ← S&P +1% → PYPL +β%
A11: R² | B11: =RSQ('📈 Доходности'!C6:C130,'📈 Доходности'!I6:I130) -> 0.2215997 | C11: RSQ | E11: =TEXT(B11*100,"0")&"% движений PYPL объяснены рынком" -> 22% движений PYPL объяснены рынком
A13: 📊 ПРОГНОЗ ДОХОДНОСТИ PYPL ПО S&P 500
A14: 📌 TREND(PYPL_все, SP500_все, SP500_текущий)
A16: День | B16: S&P500 факт (%) | D16: PYPL факт (%) | E16: PYPL прогноз (%) | F16: Ошибка | G16: e²
A17: 2 | B17: ='📈 Доходности'!I6 -> -0.0058581363 | D17: ='📈 Доходности'!C6 -> -0.0069194176 | E17: =TREND('📈 Доходности'!C6:C130,'📈 Доходности'!I6:I130,'📈 Доходности'!I6) -> -0.014833775 | F17: =D17-E17 -> 0.0079143575 | G17: =F17^2 -> 6.2637054e-05
A18: 3 | B18: ='📈 Доходности'!I7 -> -0.0024316176 | D18: ='📈 Доходности'!C7 -> -0.014080418 | E18: =TREND('📈 Доходности'!C6:C130,'📈 Доходности'!I6:I130,'📈 Доходности'!I7) -> -0.0089180579 | F18: =D18-E18 -> -0.0051623601 | G18: =F18^2 -> 2.6649962e-05
A19: 4 | B19: ='📈 Доходности'!I8 -> -0.0040042028 | D19: ='📈 Доходности'!C8 -> -0.007803298 | E19: =TREND('📈 Доходности'!C6:C130,'📈 Доходности'!I6:I130,'📈 Доходности'!I8) -> -0.011633049 | F19: =D19-E19 -> 0.0038297514 | G19: =F19^2 -> 1.4666996e-05
A20: 5 | B20: ='📈 Доходности'!I9 -> 0.015186408 | D20: ='📈 Доходности'!C9 -> 0.034871643 | E20: =TREND('📈 Доходности'!C6:C130,'📈 Доходности'!I6:I130,'📈 Доходности'!I9) -> 0.021498602 | F20: =D20-E20 -> 0.013373041 | G20: =F20^2 -> 0.00017883822
A21: 6 | B21: ='📈 Доходности'!I10 -> -0.0042663343 | D21: ='📈 Доходности'!C10 -> -0.0060223688 | E21: =TREND('📈 Доходности'!C6:C130,'📈 Доходности'!I6:I130,'📈 Доходности'!I10) -> -0.012085607 | F21: =D21-E21 -> 0.0060632379 | G21: =F21^2 -> 3.6762853e-05
A22: 7 | B22: ='📈 Доходности'!I11 -> 0.0041339769 | D22: ='📈 Доходности'!C11 -> 0.010098096 | E22: =TREND('📈 Доходности'!C6:C130,'📈 Доходности'!I6:I130,'📈 Доходности'!I11) -> 0.00241712 | F22: =D22-E22 -> 0.0076809758 | G22: =F22^2 -> 5.8997389e-05
A23: 8 | B23: ='📈 Доходности'!I12 -> 0.0023909903 | D23: ='📈 Доходности'!C12 -> -0.0075692659 | E23: =TREND('📈 Доходности'!C6:C130,'📈 Доходности'!I6:I130,'📈 Доходности'!I12) -> -0.0005920611 | F23: =D23-E23 -> -0.0069772048 | G23: =F23^2 -> 4.8681387e-05
A24: 9 | B24: ='📈 Доходности'!I13 -> 0.0031567254 | D24: ='📈 Доходности'!C13 -> 0.0059001295 | E24: =TREND('📈 Доходности'!C6:C130,'📈 Доходности'!I6:I130,'📈 Доходности'!I13) -> 0.00072994307 | F24: =D24-E24 -> 0.0051701864 | G24: =F24^2 -> 2.6730828e-05
A25: 10 | B25: ='📈 Доходности'!I14 -> -0.0063981691 | D25: ='📈 Доходности'!C14 -> 0.0018597997 | E25: =TREND('📈 Доходности'!C6:C130,'📈 Доходности'!I6:I130,'📈 Доходности'!I14) -> -0.015766115 | F25: =D25-E25 -> 0.017625915 | G25: =F25^2 -> 0.00031067288
A26: 11 | B26: ='📈 Доходности'!I15 -> -0.006922322 | D26: ='📈 Доходности'!C15 -> -0.013422819 | E26: =TREND('📈 Доходности'!C6:C130,'📈 Доходности'!I6:I130,'📈 Доходности'!I15) -> -0.01667104 | F26: =D26-E26 -> 0.0032482208 | G26: =F26^2 -> 1.0550938e-05
A27: 12 | B27: ='📈 Доходности'!I16 -> 0.0051001163 | D27: ='📈 Доходности'!C16 -> 0.0056448111 | E27: =TREND('📈 Доходности'!C6:C130,'📈 Доходности'!I6:I130,'📈 Доходности'!I16) -> 0.0040851124 | F27: =D27-E27 -> 0.0015596987 | G27: =F27^2 -> 2.43266e-06
A28: 13 | B28: ='📈 Доходности'!I17 -> 0.0083464376 | D28: ='📈 Доходности'!C17 -> -0.016983305 | E28: =TREND('📈 Доходности'!C6:C130,'📈 Доходности'!I6:I130,'📈 Доходности'!I17) -> 0.0096897276 | F28: =D28-E28 -> -0.026673032 | G28: =F28^2 -> 0.00071145064
A29: 14 | B29: ='📈 Доходности'!I18 -> -0.003165141 | D29: ='📈 Доходности'!C18 -> -0.0029282577 | E29: =TREND('📈 Доходности'!C6:C130,'📈 Доходности'!I6:I130,'📈 Доходности'!I18) -> -0.01018445 | F29: =D29-E29 -> 0.0072561926 | G29: =F29^2 -> 5.2652331e-05
A30: 15 | B30: ='📈 Доходности'!I19 -> 0.002105994 | D30: ='📈 Доходности'!C19 -> 0.0020558003 | E30: =TREND('📈 Доходности'!C6:C130,'📈 Доходности'!I6:I130,'📈 Доходности'!I19) -> -0.0010840934 | F30: =D30-E30 -> 0.0031398937 | G30: =F30^2 -> 9.8589322e-06
A31: 16 | B31: ='📈 Доходности'!I20 -> 0.0026881596 | D31: ='📈 Доходности'!C20 -> -0.010550996 | E31: =TREND('📈 Доходности'!C6:C130,'📈 Доходности'!I6:I130,'📈 Доходности'!I20) -> -7.9012836e-05 | F31: =D31-E31 -> -0.010471984 | G31: =F31^2 -> 0.00010966244
A32: 17 | B32: ='📈 Доходности'!I21 -> 0.0029834429 | D32: ='📈 Доходности'!C21 -> -0.030065166 | E32: =TREND('📈 Доходности'!C6:C130,'📈 Доходности'!I6:I130,'📈 Доходности'!I21) -> 0.00043077928 | F32: =D32-E32 -> -0.030495945 | G32: =F32^2 -> 0.00093000267
A33: 18 | B33: ='📈 Доходности'!I22 -> 0.0084858635 | D33: ='📈 Доходности'!C22 -> 0.024736601 | E33: =TREND('📈 Доходности'!C6:C130,'📈 Доходности'!I6:I130,'📈 Доходности'!I22) -> 0.0099304395 | F33: =D33-E33 -> 0.014806161 | G33: =F33^2 -> 0.00021922242
A34: 19 | B34: ='📈 Доходности'!I23 -> -0.00048273465 | D34: ='📈 Доходности'!C23 -> -0.0055133363 | E34: =TREND('📈 Доходности'!C6:C130,'📈 Доходности'!I6:I130,'📈 Доходности'!I23) -> -0.0055534068 | F34: =D34-E34 -> 4.0070486e-05 | G34: =F34^2 -> 1.6056439e-09
A35: 20 | B35: ='📈 Доходности'!I24 -> 0.0047066578 | D35: ='📈 Доходности'!C24 -> 0.003296374 | E35: =TREND('📈 Доходности'!C6:C130,'📈 Доходности'!I6:I130,'📈 Доходности'!I24) -> 0.0034058256 | F35: =D35-E35 -> -0.00010945163 | G35: =F35^2 -> 1.197966e-08
A36: 21 | B36: ='📈 Доходности'!I25 -> -0.0012879273 | D36: ='📈 Доходности'!C25 -> -0.0038829152 | E36: =TREND('📈 Доходности'!C6:C130,'📈 Доходности'!I6:I130,'📈 Доходности'!I25) -> -0.0069435326 | F36: =D36-E36 -> 0.0030606175 | G36: =F36^2 -> 9.3673792e-06
A37: 22 | B37: ='📈 Доходности'!I26 -> -0.00097021838 | D37: ='📈 Доходности'!C26 -> 0.026386807 | E37: =TREND('📈 Доходности'!C6:C130,'📈 Доходности'!I6:I130,'📈 Доходности'!I26) -> -0.0063950236 | F37: =D37-E37 -> 0.03278183 | G37: =F37^2 -> 0.0010746484
A38: 23 | B38: ='📈 Доходности'!I27 -> 0.00478914 | D38: ='📈 Доходности'!C27 -> -0.001460707 | E38: =TREND('📈 Доходности'!C6:C130,'📈 Доходности'!I6:I130,'📈 Доходности'!I27) -> 0.003548227 | F38: =D38-E38 -> -0.005008934 | G38: =F38^2 -> 2.508942e-05
A39: 24 | B39: ='📈 Доходности'!I28 -> 0.0048854336 | D39: ='📈 Доходности'!C28 -> -0.0043885313 | E39: =TREND('📈 Доходности'!C6:C130,'📈 Доходности'!I6:I130,'📈 Доходности'!I28) -> 0.0037144732 | F39: =D39-E39 -> -0.0081030045 | G39: =F39^2 -> 6.5658682e-05
A40: 25 | B40: ='📈 Доходности'!I29 -> 0.0044100259 | D40: ='📈 Доходности'!C29 -> -0.0079341757 | E40: =TREND('📈 Доходности'!C6:C130,'📈 Доходности'!I6:I130,'📈 Доходности'!I29) -> 0.0028937051 | F40: =D40-E40 -> -0.010827881 | G40: =F40^2 -> 0.000117243
A41: 26 | B41: ='📈 Доходности'!I30 -> -0.0055021475 | D41: ='📈 Доходности'!C30 -> -0.0054798578 | E41: =TREND('📈 Доходности'!C6:C130,'📈 Доходности'!I6:I130,'📈 Доходности'!I30) -> -0.014219178 | F41: =D41-E41 -> 0.00873932 | G41: =F41^2 -> 7.6375713e-05
A42: 27 | B42: ='📈 Доходности'!I31 -> -0.0028466618 | D42: ='📈 Доходности'!C31 -> 0.008190618 | E42: =TREND('📈 Доходности'!C6:C130,'📈 Доходности'!I6:I130,'📈 Доходности'!I31) -> -0.0096346115 | F42: =D42-E42 -> 0.01782523 | G42: =F42^2 -> 0.00031773881
A43: 28 | B43: ='📈 Доходности'!I32 -> -0.0050090615 | D43: ='📈 Доходности'!C32 -> -0.016395864 | E43: =TREND('📈 Доходности'!C6:C130,'📈 Доходности'!I6:I130,'📈 Доходности'!I32) -> -0.013367889 | F43: =D43-E43 -> -0.0030279752 | G43: =F43^2 -> 9.168634e-06
A44: 29 | B44: ='📈 Доходности'!I33 -> 0.0059018399 | D44: ='📈 Доходности'!C33 -> 0.0082594984 | E44: =TREND('📈 Доходности'!C6:C130,'📈 Доходности'!I6:I130,'📈 Доходности'!I33) -> 0.0054692491 | F44: =D44-E44 -> 0.0027902494 | G44: =F44^2 -> 7.7854915e-06
...

Sheet 🏅 Ранговые методы
A1: 🏅 РАНГОВЫЕ МЕТОДЫ (РЕАЛЬНЫЕ ДАННЫЕ)
A3: 📊 СПИРМЕН: PYPL ↔ MA (n=20 дней)
A4: Paypal и Mastercard и — компании цифровых платежей. Ранги доходностей совпадают?
A6: День | B6: PYPL (%) | C6: MA (%) | D6: Ранг PYPL | E6: Ранг MA | F6: d | G6: d²
A7: 2 | B7: ='📈 Доходности'!C6 -> -0.0069194176 | C7: ='📈 Доходности'!E6 -> 0.0023519717 | D7: =RANK(B7,$B$7:$B$26) -> 13 | E7: =RANK(C7,$C$7:$C$26) -> 10 | F7: =D7-E7 -> 3 | G7: =F7^2 -> 9
A8: 3 | B8: ='📈 Доходности'!C7 -> -0.014080418 | C8: ='📈 Доходности'!E7 -> 0.012246086 | D8: =RANK(B8,$B$7:$B$26) -> 18 | E8: =RANK(C8,$C$7:$C$26) -> 2 | F8: =D8-E8 -> 16 | G8: =F8^2 -> 256
A9: 4 | B9: ='📈 Доходности'!C8 -> -0.007803298 | C9: ='📈 Доходности'!E8 -> -0.0012859342 | D9: =RANK(B9,$B$7:$B$26) -> 15 | E9: =RANK(C9,$C$7:$C$26) -> 12 | F9: =D9-E9 -> 3 | G9: =F9^2 -> 9
A10: 5 | B10: ='📈 Доходности'!C9 -> 0.034871643 | C10: ='📈 Доходности'!E9 -> 0.011893266 | D10: =RANK(B10,$B$7:$B$26) -> 1 | E10: =RANK(C10,$C$7:$C$26) -> 3 | F10: =D10-E10 -> -2 | G10: =F10^2 -> 4
A11: 6 | B11: ='📈 Доходности'!C10 -> -0.0060223688 | C11: ='📈 Доходности'!E10 -> -0.0095936511 | D11: =RANK(B11,$B$7:$B$26) -> 12 | E11: =RANK(C11,$C$7:$C$26) -> 18 | F11: =D11-E11 -> -6 | G11: =F11^2 -> 36
A12: 7 | B12: ='📈 Доходности'!C11 -> 0.010098096 | C12: ='📈 Доходности'!E11 -> -0.0027048044 | D12: =RANK(B12,$B$7:$B$26) -> 3 | E12: =RANK(C12,$C$7:$C$26) -> 14 | F12: =D12-E12 -> -11 | G12: =F12^2 -> 121
A13: 8 | B13: ='📈 Доходности'!C12 -> -0.0075692659 | C13: ='📈 Доходности'!E12 -> -0.0015933824 | D13: =RANK(B13,$B$7:$B$26) -> 14 | E13: =RANK(C13,$C$7:$C$26) -> 13 | F13: =D13-E13 -> 1 | G13: =F13^2 -> 1
A14: 9 | B14: ='📈 Доходности'!C13 -> 0.0059001295 | C14: ='📈 Доходности'!E13 -> -0.00030560272 | D14: =RANK(B14,$B$7:$B$26) -> 4 | E14: =RANK(C14,$C$7:$C$26) -> 11 | F14: =D14-E14 -> -7 | G14: =F14^2 -> 49
A15: 10 | B15: ='📈 Доходности'!C14 -> 0.0018597997 | C15: ='📈 Доходности'!E14 -> 0.0081349139 | D15: =RANK(B15,$B$7:$B$26) -> 8 | E15: =RANK(C15,$C$7:$C$26) -> 4 | F15: =D15-E15 -> 4 | G15: =F15^2 -> 16
A16: 11 | B16: ='📈 Доходности'!C15 -> -0.013422819 | C16: ='📈 Доходности'!E15 -> -0.0057445124 | D16: =RANK(B16,$B$7:$B$26) -> 17 | E16: =RANK(C16,$C$7:$C$26) -> 16 | F16: =D16-E16 -> 1 | G16: =F16^2 -> 1
A17: 12 | B17: ='📈 Доходности'!C16 -> 0.0056448111 | C17: ='📈 Доходности'!E16 -> 0.0023890207 | D17: =RANK(B17,$B$7:$B$26) -> 5 | E17: =RANK(C17,$C$7:$C$26) -> 9 | F17: =D17-E17 -> -4 | G17: =F17^2 -> 16
A18: 13 | B18: ='📈 Доходности'!C17 -> -0.016983305 | C18: ='📈 Доходности'!E17 -> 0.0039722114 | D18: =RANK(B18,$B$7:$B$26) -> 19 | E18: =RANK(C18,$C$7:$C$26) -> 8 | F18: =D18-E18 -> 11 | G18: =F18^2 -> 121
... A26: 21 | B26: ='📈 Доходности'!C25 -> -0.0038829152 | C26: ='📈 Доходности'!E25 -> 0.0059347691 | D26: =RANK(B26,$B$7:$B$26) -> 10 | E26: =RANK(C26,$C$7:$C$26) -> 5 | F26: =D26-E26 -> 5 | G26: =F26^2 -> 25
A28: Σd² = | B28: =SUM(G7:G26) -> 860
A29: ρ Спирмена = | B29: =1-(6*B28)/(20*(20^2-1)) -> 0.35338346
A30: Проверка = | B30: =CORREL(D7:D26,E7:E26) -> 0.35338346 | C30: ← Должно совпасть
A31: Сила: | B31: =IF(ABS(B29)>=0.7,"🟢 Сильная",IF(ABS(B29)>=0.3,"🟡 Средняя","🔴 Слабая")) -> 🟡 Средняя
A34: 📊 МАНН-УИТНИ: GOOGL vs BAIDF (доходности)
A35: Google и Baidu — разные страны?
A37: GOOGL (%) | B37: Ранг | D37: BAIDF (%) | E37: Ранг
A38: ='📈 Доходности'!F6 -> -0.0094984989 | B38: {=SUMPRODUCT(($A$38:$A$45>A38)*1)+SUMPRODUCT(($D$38:$D$45>A38)*1)+1} -> 15 | D38: ='📈 Доходности'!H6 -> 0 | E38: =SUMPRODUCT(($A$38:$A$45>D38)*1)+SUMPRODUCT(($D$38:$D$45>D38)*1)+1 -> 7
A39: ='📈 Доходности'!F7 -> -0.011179569 | B39: =SUMPRODUCT(($A$38:$A$45>A39)*1)+SUMPRODUCT(($D$38:$D$45>A39)*1)+1 -> 16 | D39: ='📈 Доходности'!H7 -> 0 | E39: =SUMPRODUCT(($A$38:$A$45>D39)*1)+SUMPRODUCT(($D$38:$D$45>D39)*1)+1 -> 7
A40: ='📈 Доходности'!F8 -> 0.0021606954 | B40: =SUMPRODUCT(($A$38:$A$45>A40)*1)+SUMPRODUCT(($D$38:$D$45>A40)*1)+1 -> 5 | D40: ='📈 Доходности'!H8 -> 0 | E40: =SUMPRODUCT(($A$38:$A$45>D40)*1)+SUMPRODUCT(($D$38:$D$45>D40)*1)+1 -> 7
A41: ='📈 Доходности'!F9 -> 0.031738869 | B41: =SUMPRODUCT(($A$38:$A$45>A41)*1)+SUMPRODUCT(($D$38:$D$45>A41)*1)+1 -> 1 | D41: ='📈 Доходности'!H9 -> 0 | E41: =SUMPRODUCT(($A$38:$A$45>D41)*1)+SUMPRODUCT(($D$38:$D$45>D41)*1)+1 -> 7
A42: ='📈 Доходности'!F10 -> 0.011663508 | B42: =SUMPRODUCT(($A$38:$A$45>A42)*1)+SUMPRODUCT(($D$38:$D$45>A42)*1)+1 -> 3 | D42: ='📈 Доходности'!H10 -> 0.0098920863 | E42: =SUMPRODUCT(($A$38:$A$45>D42)*1)+SUMPRODUCT(($D$38:$D$45>D42)*1)+1 -> 4
A43: ='📈 Доходности'!F11 -> -0.0064850843 | B43: =SUMPRODUCT(($A$38:$A$45>A43)*1)+SUMPRODUCT(($D$38:$D$45>A43)*1)+1 -> 14 | D43: ='📈 Доходности'!H11 -> -0.0026714159 | E43: =SUMPRODUCT(($A$38:$A$45>D43)*1)+SUMPRODUCT(($D$38:$D$45>D43)*1)+1 -> 13
A44: ='📈 Доходности'!F12 -> 0.0016439416 | B44: =SUMPRODUCT(($A$38:$A$45>A44)*1)+SUMPRODUCT(($D$38:$D$45>A44)*1)+1 -> 6 | D44: ='📈 Доходности'!H12 -> 0 | E44: =SUMPRODUCT(($A$38:$A$45>D44)*1)+SUMPRODUCT(($D$38:$D$45>D44)*1)+1 -> 7
A45: ='📈 Доходности'!F13 -> 0.020032825 | B45: =SUMPRODUCT(($A$38:$A$45>A45)*1)+SUMPRODUCT(($D$38:$D$45>A45)*1)+1 -> 2 | D45: ='📈 Доходности'!H13 -> 0 | E45: =SUMPRODUCT(($A$38:$A$45>D45)*1)+SUMPRODUCT(($D$38:$D$45>D45)*1)+1 -> 7
A47: R₁ (Σ рангов TSLA) | D47: =SUM(B38:B45) -> 62
A48: R₂ (Σ рангов JPM) | D48: =SUM(E38:E45) -> 59
A49: U₁ | D49: =8*8+8*(8+1)/2-D47 -> 38
A50: U₂ | D50: =8*8+8*(8+1)/2-D48 -> 41
A51: U = MIN(U₁,U₂) | D51: =MIN(D49,D50) -> 38
A52: U_крит (α=0.05) | D52: 13
A53: РЕЗУЛЬТАТ: | D53: =IF(D51<=D52,"✅ Секторы РАЗЛИЧАЮТСЯ","❌ Различий НЕТ") -> ❌ Различий НЕТ

Sheet ⭐ Бонус
A1: ⭐ БОНУС: ЧАСТНАЯ КОРРЕЛЯЦИЯ + COHEN'S d
A3: 🟣 ЧАСТНАЯ КОРРЕЛЯЦИЯ: PYPL&BAIDF | S&P500
A4: PYPL&BAIDF коррелируют. Но может это просто потому что ОБА следуют за S&P500?
A6: Шаг | B6: Что считаем | D6: Значение | E6: Пояснение
A7: 1 | B7: r(PYPL, BAIDF) | D7: =CORREL('📈 Доходности'!C6:C130,'📈 Доходности'!H6:H130) -> 0.20500636 | E7: ← Обычная корреляция (может быть из-за рынка)
A8: 2 | B8: r(PYPL, S&P500) | D8: =CORREL('📈 Доходности'!C6:C130,'📈 Доходности'!I6:I130) -> 0.47074377
A9: 3 | B9: r(BAIDF, S&P500) | D9: =CORREL('📈 Доходности'!H6:H130,'📈 Доходности'!I6:I130) -> 0.075406928
A10: 4 ✨ | B10: r_partial | D10: =(D7-D8*D9)/SQRT((1-D8^2)*(1-D9^2)) -> 0.19267686 | E10: ← ЧИСТАЯ связь PYPL↔BAIDF без рынка!
A13: 🟡 COHEN'S d: PYPL первая пол. vs вторая пол.
A14: Изменился ли характер PYPL во второй половине периода?
A16: Шаг | B16: Показатель | D16: Значение | E16: Пояснение
A17: 1 | B17: M₁ (1-я половина) | D17: =AVERAGE('📈 Доходности'!C6:C20) -> -0.0017233245
A18: 2 | B18: M₂ (2-я половина) | D18: =AVERAGE('📈 Доходности'!C21:G130) -> 0.00048308425
A19: 3 | B19: SD₁ | D19: =STDEV('📈 Доходности'!C6:C20) -> 0.012919834
A20: 4 | B20: SD₂ | D20: =STDEV('📈 Доходности'!C21:C130) -> 0.028089901
A21: 5 | B21: SD_pooled | D21: =SQRT((D19^2+D20^2)/2) -> 0.021862807
A22: 6 ✨ | B22: Cohen's d | D22: =(D17-D18)/D21 -> -0.10092065 | E22: =IF(ABS(D22)>=0.8,"Большой ⬆️ Тренд!",IF(ABS(D22)>=0.5,"Средний ➡️","Малый ⬇️ Стабильно")) -> Малый ⬇️ Стабильно

Sheet 6 бонус
C7: 10000 | D7: =C7/6 -> 1666.6667
D8: =$D$7/D9 -> 24.025756 | E8: =$D$7/E9 -> 6.2902576 | F8: =$D$7/F9 -> 2.8612794 | G8: =$D$7/G9 -> 8.2025034 | H8: =$D$7/H9 -> 16.583748 | I8: =$D$7/I9 -> 149.8801
C9: день покупки | D9: ='📊 Цены'!C4 -> 69.37 | E9: ='📊 Цены'!D4 -> 264.96 | F9: ='📊 Цены'!E4 -> 582.49 | G9: ='📊 Цены'!F4 -> 203.19 | H9: ='📊 Цены'!G4 -> 100.5 | I9: ='📊 Цены'!H4 -> 11.12
C10: день продажи | D10: ='📊 Цены'!C129 -> 40.81 | E10: ='📊 Цены'!D129 -> 359.94 | F10: ='📊 Цены'!E129 -> 521.93 | G10: ='📊 Цены'!F129 -> 302.02 | H10: ='📊 Цены'!G129 -> 128.85 | I10: ='📊 Цены'!H129 -> 17.94
C11: доход | D11: =((D10-D9))*D8 -> -686.17558 | E11: =((E10-E9))*E8 -> 597.44867 | F11: =((F10-F9))*F8 -> -173.27908 | G11: =((G10-G9))*G8 -> 810.65341 | H11: =((H10-H9))*H8 -> 470.14925 | I11: =((I10-I9))*I8 -> 1022.1823
C12: итого по акциям | D12: =$D$7+D11 -> 980.49109 | E12: =$D$7+E11 -> 2264.1153 | F12: =$D$7+F11 -> 1493.3876 | G12: =$D$7+G11 -> 2477.3201 | H12: =$D$7+H11 -> 2136.8159 | I12: =$D$7+I11 -> 2688.8489 | J12: =SUM(D12:I12) -> 12040.979
